Workbook

Sheet 10 elementos
B1: Resultados Pyphi | E1: GeoMIP | H1: Analisis de error y precision | J1: rendimiento temporal | K1: se calculo con respecto a pyphi
A2: Subsistema | B2: Particion | C2: Perdida | D2: Tiempo | E2: Particion5 | F2: Perdida6 | G2: Tiempo Total | H2: error relativo | I2: tasa de acierto | J2: speedup
A3: ABCDEFGHIJ_{t+1}|ABCDEFGHIJ_{t} | B3: [[['I'],['∅']],[['A','B','C','D','E','F','G','H','J'],['a','b','c','d','e','f','g','h','i','j']]] | C3: 0.472656 | D3: 109.19606 | E3: [[['I'],['∅']],[['A','B','C','D','E','F','G','H','J'],['a','b','c','d','e','f','g','h','i','j']]] | F3: 0.47265625 | G3: 0.25284004 | H3: =IF('10 elementos'!$C3=0, IF('10 elementos'!$F3=0, 0, "Indefinido"), ABS('10 elementos'!$C3-'10 elementos'!$F3)/'10 elementos'!$C3) -> 5.289259e-07 | I3: 1 | J3: ='10 elementos'!$D3/'10 elementos'!$G3 -> 431.87804
A4: ABCDEFGHIJ_{t+1}|ABCDEFGHI_{t} | B4: [[['G'], ['∅']], [['A','B','C','D','E','F','H','I','J'], ['a','b','c','d','e','f','g','h','i']]] | C4: 0.004883 | D4: 52.820366 | E4: [[['G'],['∅']],[['A','B','C','D','E','F','H','I','J'],['a','b','c','d','e','f','g','h','i']]] | F4: 0.0048828125 | G4: 0.13605738 | H4: =IF('10 elementos'!$C4=0, IF('10 elementos'!$F4=0, 0, "Indefinido"), ABS('10 elementos'!$C4-'10 elementos'!$F4)/'10 elementos'!$C4) -> 3.8398525e-05 | I4: 1 | J4: ='10 elementos'!$D4/'10 elementos'!$G4 -> 388.22126
A5: ABCDEFGHIJ_{t+1}|BCDEFGHIJ_{t} | B5: [[['G'], ['∅']], [['A','B','C','D','E','F','H','I','J'], ['b','c','d','e','f','g','h','i','j']]] | C5: 0.004883 | D5: 50.810333 | E5: [[['G'],['∅']],[['A','B','C','D','E','F','H','I','J'],['c','d','e','f','g','h','i','j']]] | F5: 0.0048828125 | G5: 0.13763261 | H5: =IF('10 elementos'!$C5=0, IF('10 elementos'!$F5=0, 0, "Indefinido"), ABS('10 elementos'!$C5-'10 elementos'!$F5)/'10 elementos'!$C5) -> 3.8398525e-05 | I5: 1 | J5: ='10 elementos'!$D5/'10 elementos'!$G5 -> 369.17365
A6: ABCDEFGHI_{t+1}|ABCDEFGHIJ_{t} | B6: [[['I'], ['∅']], [['A','B','C','D','E','F','G','H'], ['a','b','c','d','e','f','g','h','i','j']]] | C6: 0.472656 | D6: 57.439945 | E6: [[['I'],['∅']],[['A','B','C','D','E','F','G','H'],['a','b','c','d','e','f','g','h','i','j']]] | F6: 0.47265625 | G6: 0.24005461 | H6: =IF('10 elementos'!$C6=0, IF('10 elementos'!$F6=0, 0, "Indefinido"), ABS('10 elementos'!$C6-'10 elementos'!$F6)/'10 elementos'!$C6) -> 5.289259e-07 | I6: 1 | J6: ='10 elementos'!$D6/'10 elementos'!$G6 -> 239.27866
A7: BCDEFGHIJ_{t+1}|ABCDEFGHIJ_{t} | B7: [[['I'], ['∅']], [['B','C','D','E','F','G','H','J'], ['a','b','c','d','e','f','g','h','i','j']]] | C7: 0.472656 | D7: 45.450145 | E7: [[['I'],['∅']],[['B','C','D','E','F','G','H','J'],['a','b','c','d','e','f','g','h','i','j']]] | F7: 0.47265625 | G7: 0.29289031 | H7: =IF('10 elementos'!$C7=0, IF('10 elementos'!$F7=0, 0, "Indefinido"), ABS('10 elementos'!$C7-'10 elementos'!$F7)/'10 elementos'!$C7) -> 5.289259e-07 | I7: 1 | J7: ='10 elementos'!$D7/'10 elementos'!$G7 -> 155.17804
A8: ABCDEFGHIJ_{t+1}|BCDEFGHI_{t} | B8: [[['B'], ['∅']], [['A','C','D','E','F','G','H','I','J'], ['b','c','d','e','f','g','h','i']]] | C8: 0.011719 | D8: 25.113385 | E8: [[['H'],['∅']],[['A','B','C','D','E','F','G','I','J'],['c','d','e','f','g','h','i']]] | F8: 0.01171875 | G8: 0.076529264 | H8: =IF('10 elementos'!$C8=0, IF('10 elementos'!$F8=0, 0, "Indefinido"), ABS('10 elementos'!$C8-'10 elementos'!$F8)/'10 elementos'!$C8) -> 2.1332878e-05 | I8: 0 | J8: ='10 elementos'!$D8/'10 elementos'!$G8 -> 328.15401
A9: ABCDEFGHI_{t+1}|ABCDEFGHI_{t} | B9: [[['G'], ['∅']], [['A','B','C','D','E','F','H','I'], ['a','b','c','d','e','f','g','h','i']]] | C9: 0.004883 | D9: 24.022703 | E9: [[['G'],['∅']],[['A','B','C','D','E','F','H','I'],['a','b','c','d','e','f','g','h','i']]] | F9: 0.0048828125 | G9: 0.13067532 | H9: =IF('10 elementos'!$C9=0, IF('10 elementos'!$F9=0, 0, "Indefinido"), ABS('10 elementos'!$C9-'10 elementos'!$F9)/'10 elementos'!$C9) -> 3.8398525e-05 | I9: 1 | J9: ='10 elementos'!$D9/'10 elementos'!$G9 -> 183.83505
A10: ABCDEFGHI_{t+1}|BCDEFGHIJ_{t} | B10: [[['G'], ['∅']], [['A','B','C','D','E','F','H','I'], ['b','c','d','e','f','g','h','i','j']]] | C10: 0.004883 | D10: 22.773661 | E10: [[['G'],['∅']],[['A','B','C','D','E','F','H','I'],['c','d','e','f','g','h','i','j']]] | F10: 0.0048828125 | G10: 0.12130737 | H10: =IF('10 elementos'!$C10=0, IF('10 elementos'!$F10=0, 0, "Indefinido"), ABS('10 elementos'!$C10-'10 elementos'!$F10)/'10 elementos'!$C10) -> 3.8398525e-05 | I10: 1 | J10: ='10 elementos'!$D10/'10 elementos'!$G10 -> 187.73517
A11: BCDEFGHIJ_{t+1}|ABCDEFGHI_{t} | B11: [[['G'], ['∅']], [['B','C','D','E','F','H','I','J'], ['a','b','c','d','e','f','g','h','i']]] | C11: 0.004883 | D11: 22.967752 | E11: [[['G'],['∅']],[['B','C','D','E','F','H','I','J'],['a','b','c','d','e','f','g','h','i']]] | F11: 0.0048828125 | G11: 0.12152481 | H11: =IF('10 elementos'!$C11=0, IF('10 elementos'!$F11=0, 0, "Indefinido"), ABS('10 elementos'!$C11-'10 elementos'!$F11)/'10 elementos'!$C11) -> 3.8398525e-05 | I11: 1 | J11: ='10 elementos'!$D11/'10 elementos'!$G11 -> 188.99641
A12: BCDEFGHIJ_{t+1}|BCDEFGHIJ_{t} | B12: [[['G'], ['∅']], [['B','C','D','E','F','H','I','J'], ['b','c','d','e','f','g','h','i','j']]] | C12: 0.004883 | D12: 22.794874 | E12: [[['G'],['∅']],[['B','C','D','E','F','H','I','J'],['c','d','e','f','g','h','i','j']]] | F12: 0.0048828125 | G12: 0.12075472 | H12: =IF('10 elementos'!$C12=0, IF('10 elementos'!$F12=0, 0, "Indefinido"), ABS('10 elementos'!$C12-'10 elementos'!$F12)/'10 elementos'!$C12) -> 3.8398525e-05 | I12: 1 | J12: ='10 elementos'!$D12/'10 elementos'!$G12 -> 188.77005
A13: BCDEFGHI_{t+1}|ABCDEFGHIJ_{t} | B13: [[['I'], ['∅']], [['B','C','D','E','F','G','H'], ['a','b','c','d','e','f','g','h','i','j']]] | C13: 0.472656 | D13: 21.239982 | E13: [[['I'],['∅']],[['B','C','D','E','F','G','H'],['a','b','c','d','e','f','g','h','i','j']]] | F13: 0.47265625 | G13: 0.2058723 | H13: =IF('10 elementos'!$C13=0, IF('10 elementos'!$F13=0, 0, "Indefinido"), ABS('10 elementos'!$C13-'10 elementos'!$F13)/'10 elementos'!$C13) -> 5.289259e-07 | I13: 1 | J13: ='10 elementos'!$D13/'10 elementos'!$G13 -> 103.17067
A14: ABCDEFGHIJ_{t+1}|ABDEGHJ_{t} | B14: [[['J'], ['∅']], [['A','B','C','D','E','F','G','H','I'], ['a','b','d','e','g','h','j']]] | C14: 0.005859 | D14: 12.668935 | E14: [[['J'],['∅']],[['A','B','C','D','E','F','G','H','I'],['a','b','e','g','j']]] | F14: 0.005859375 | G14: 0.047006845 | H14: =IF('10 elementos'!$C14=0, IF('10 elementos'!$F14=0, 0, "Indefinido"), ABS('10 elementos'!$C14-'10 elementos'!$F14)/'10 elementos'!$C14) -> 6.4004096e-05 | I14: 1 | J14: ='10 elementos'!$D14/'10 elementos'!$G14 -> 269.51256
... A52: BDFHJ_{t+1}|BDFHJ_{t} | B52: [[['F'], ['∅']], [['B','D','H','J'], ['b','d','f','h','j']]] | C52: 0.024414 | D52: 0.12887454 | E52: [[['F'],['∅']],[['B','D','H','J'],['d','h']]] | F52: 0.024414062 | G52: 0.013553381 | H52: =IF('10 elementos'!$C52=0, IF('10 elementos'!$F52=0, 0, "Indefinido"), ABS('10 elementos'!$C52-'10 elementos'!$F52)/'10 elementos'!$C52) -> 2.5600066e-06 | I52: 1 | J52: ='10 elementos'!$D52/'10 elementos'!$G52 -> 9.5086636

Sheet 15A elementos
B1: Resultados Pyphi | E1: EstrategiaQ | H1: GeoMIP | K1: Analisis de error y precision | M1: rendimiento temporal
A2: Subsistema | B2: Particion | C2: Perdida | D2: Tiempo | E2: Particion5 | F2: Perdida6 | G2: Tiempo7 | H2: Particion5 | I2: Perdida6 | J2: Tiempo ejecución | K2: error relativo | L2: tasa de acierto | M2: speedup
A3: ABCDEFGHIJKLMNO_{t+1}|ABCDEFGHIJKLMNO_{t} | B3: [[['∅'], ['a']], [['A','B','C','D','E','F','G','H','I','J','K','L','M','N','O'], ['b','c','d','e','f','g','h','i','j','k','l','m','n','o']]] | C3: 0 | D3: 28.802977 | E3: [[['∅'], ['i']], [['A', 'B', 'C', 'D', 'E', 'F', 'G', 'H', 'I', 'J', 'K', 'L', 'M', 'N', 'O'], ['a', 'b', 'c', 'd', 'e', 'f', 'g', 'h', 'j', 'k', 'l', 'm', 'n', 'o']]] | F3: 0 | G3: 3.194104 | H3: [[['∅'],['o']],[['A','B','C','D','E','F','G','H','I','J','K','L','M','N','O'],['a','b','c','d','e','f','g','h','i','j','k','l','m','n']]] | I3: 0 | J3: 1.8886199 | K3: =IF('15A elementos'!$F3=0, IF('15A elementos'!$I3=0, 0, "Indefinido"), ABS('15A elementos'!$F3-'15A elementos'!$I3)/'15A elementos'!$F3) -> 0 | L3: 1 | M3: ='15A elementos'!$G3/'15A elementos'!$J3 -> 1.6912371
A4: ABCDEFGHIJKLMNO_{t+1}|ABCDEFGHIJKLMN_{t} | B4: [[['∅'], ['a']], [['A','B','C','D','E','F','G','H','I','J','K','L','M','N','O'], ['b','c','d','e','f','g','h','i','j','k','l','m','n']]] | C4: 0 | D4: 28.398227 | E4: [[['∅'], ['m']], [['A', 'B', 'C', 'D', 'E', 'F', 'G', 'H', 'I', 'J', 'K', 'L', 'M', 'N', 'O'], ['a', 'b', 'c', 'd', 'e', 'f', 'g', 'h', 'i', 'j', 'k', 'l', 'n']]] | F4: 0 | G4: 1.6307409 | H4: [[['∅'],['m']],[['A','B','C','D','E','F','G','H','I','J','K','L','M','N','O'],['a','b','c','d','e','f','g','h','i','j','k','l','n']]] | I4: 0 | J4: 0.11499238 | K4: =IF('15A elementos'!$F4=0, IF('15A elementos'!$I4=0, 0, "Indefinido"), ABS('15A elementos'!$F4-'15A elementos'!$I4)/'15A elementos'!$F4) -> 0 | L4: 1 | M4: ='15A elementos'!$G4/'15A elementos'!$J4 -> 14.181295
A5: ABCDEFGHIJKLMNO_{t+1}|BCDEFGHIJKLMNO_{t} | B5: [[['∅'], ['b']], [['A','B','C','D','E','F','G','H','I','J','K','L','M','N','O'], ['c','d','e','f','g','h','i','j','k','l','m','n','o']]] | C5: 0 | D5: 39.622645 | E5: [[['∅'], ['o']], [['A', 'B', 'C', 'D', 'E', 'F', 'G', 'H', 'I', 'J', 'K', 'L', 'M', 'N', 'O'], ['b', 'c', 'd', 'e', 'f', 'g', 'h', 'i', 'j', 'k', 'l', 'm', 'n']]] | F5: 0 | G5: 1.568455 | H5: [[['∅'],['o']],[['A','B','C','D','E','F','G','H','I','J','K','L','M','N','O'],['b','c','d','e','f','g','h','i','j','k','l','m','n']]] | I5: 0 | J5: 1.6970785 | K5: =IF('15A elementos'!$F5=0, IF('15A elementos'!$I5=0, 0, "Indefinido"), ABS('15A elementos'!$F5-'15A elementos'!$I5)/'15A elementos'!$F5) -> 0 | L5: 1 | M5: ='15A elementos'!$G5/'15A elementos'!$J5 -> 0.92420888
A6: ABCDEFGHIJKLMN_{t+1}|ABCDEFGHIJKLMNO_{t} | B6: [[['∅'], ['a']], [['A','B','C','D','E','F','G','H','I','J','K','L','M','N'], ['b','c','d','e','f','g','h','i','j','k','l','m','n','o']]] | C6: 0 | D6: 8.6746931 | E6: [[['∅'], ['o']], [['A', 'B', 'C', 'D', 'E', 'F', 'G', 'H', 'I', 'J', 'K', 'L', 'M', 'N'], ['a', 'b', 'c', 'd', 'e', 'f', 'g', 'h', 'i', 'j', 'k', 'l', 'm', 'n']]] | F6: 0 | G6: 1.6495843 | H6: [[['∅'],['o']],[['A','B','C','D','E','F','G','H','I','J','K','L','M','N'],['a','b','c','d','e','f','g','h','i','j','k','l','m','n']]] | I6: 0 | J6: 0.23936653 | K6: =IF('15A elementos'!$F6=0, IF('15A elementos'!$I6=0, 0, "Indefinido"), ABS('15A elementos'!$F6-'15A elementos'!$I6)/'15A elementos'!$F6) -> 0 | L6: 1 | M6: ='15A elementos'!$G6/'15A elementos'!$J6 -> 6.8914576
A7: BCDEFGHIJKLMNO_{t+1}|ABCDEFGHIJKLMNO_{t} | B7: [[['∅'], ['a']], [['B','C','D','E','F','G','H','I','J','K','L','M','N','O'], ['b','c','d','e','f','g','h','i','j','k','l','m','n','o']]] | C7: 0 | D7: 8.1382196 | E7: [[['∅'], ['o']], [['B', 'C', 'D', 'E', 'F', 'G', 'H', 'I', 'J', 'K', 'L', 'M', 'N', 'O'], ['a', 'b', 'c', 'd', 'e', 'f', 'g', 'h', 'i', 'j', 'k', 'l', 'm', 'n']]] | F7: 0 | G7: 1.4506099 | H7: [[['∅'],['o']],[['B','C','D','E','F','G','H','I','J','K','L','M','N','O'],['a','b','c','d','e','f','g','h','i','j','k','l','m','n']]] | I7: 0 | J7: 1.9122262 | K7: =IF('15A elementos'!$F7=0, IF('15A elementos'!$I7=0, 0, "Indefinido"), ABS('15A elementos'!$F7-'15A elementos'!$I7)/'15A elementos'!$F7) -> 0 | L7: 1 | M7: ='15A elementos'!$G7/'15A elementos'!$J7 -> 0.75859745
A8: ABCDEFGHIJKLMNO_{t+1}|BCDEFGHIJKLMN_{t} | B8: [[['∅'], ['b']], [['A','B','C','D','E','F','G','H','I','J','K','L','M','N','O'], ['c','d','e','f','g','h','i','j','k','l','m','n']]] | C8: 0 | D8: 54.567577 | E8: [[['∅'], ['g']], [['A', 'B', 'C', 'D', 'E', 'F', 'G', 'H', 'I', 'J', 'K', 'L', 'M', 'N', 'O'], ['b', 'c', 'd', 'e', 'f', 'h', 'i', 'j', 'k', 'l', 'm', 'n']]] | F8: 0 | G8: 0.97051144 | H8: [[['∅'],['g']],[['A','B','C','D','E','F','G','H','I','J','K','L','M','N','O'],['b','c','d','e','f','h','i','j','k','l','m','n']]] | I8: 0 | J8: 0.58646607 | K8: =IF('15A elementos'!$F8=0, IF('15A elementos'!$I8=0, 0, "Indefinido"), ABS('15A elementos'!$F8-'15A elementos'!$I8)/'15A elementos'!$F8) -> 0 | L8: 1 | M8: ='15A elementos'!$G8/'15A elementos'!$J8 -> 1.6548467
A9: ABCDEFGHIJKLMN_{t+1}|ABCDEFGHIJKLMN_{t} | B9: [[['∅'], ['a']], [['A','B','C','D','E','F','G','H','I','J','K','L','M','N'], ['b','c','d','e','f','g','h','i','j','k','l','m','n']]] | C9: 0 | D9: 9.1506529 | E9: [[['∅'], ['m']], [['A', 'B', 'C', 'D', 'E', 'F', 'G', 'H', 'I', 'J', 'K', 'L', 'M', 'N'], ['a', 'b', 'c', 'd', 'e', 'f', 'g', 'h', 'i', 'j', 'k', 'l', 'n']]] | F9: 0 | G9: 0.88901186 | H9: [[['∅'],['m']],[['A','B','C','D','E','F','G','H','I','J','K','L','M','N'],['a','b','c','d','e','f','g','h','i','j','k','l','n']]] | I9: 0 | J9: 1.7541485 | K9: =IF('15A elementos'!$F9=0, IF('15A elementos'!$I9=0, 0, "Indefinido"), ABS('15A elementos'!$F9-'15A elementos'!$I9)/'15A elementos'!$F9) -> 0 | L9: 1 | M9: ='15A elementos'!$G9/'15A elementos'!$J9 -> 0.50680536
A10: ABCDEFGHIJKLMN_{t+1}|BCDEFGHIJKLMNO_{t} | B10: [[['∅'], ['b']], [['A','B','C','D','E','F','G','H','I','J','K','L','M','N'], ['c','d','e','f','g','h','i','j','k','l','m','n','o']]] | C10: 0 | D10: 9.356909 | E10: [[['∅'], ['o']], [['A', 'B', 'C', 'D', 'E', 'F', 'G', 'H', 'I', 'J', 'K', 'L', 'M', 'N'], ['b', 'c', 'd', 'e', 'f', 'g', 'h', 'i', 'j', 'k', 'l', 'm', 'n']]] | F10: 0 | G10: 0.85712123 | H10: [[['∅'],['o']],[['A','B','C','D','E','F','G','H','I','J','K','L','M','N'],['b','c','d','e','f','g','h','i','j','k','l','m','n']]] | I10: 0 | J10: 0.11715221 | K10: =IF('15A elementos'!$F10=0, IF('15A elementos'!$I10=0, 0, "Indefinido"), ABS('15A elementos'!$F10-'15A elementos'!$I10)/'15A elementos'!$F10) -> 0 | L10: 1 | M10: ='15A elementos'!$G10/'15A elementos'!$J10 -> 7.3163041
A11: BCDEFGHIJKLMNO_{t+1}|ABCDEFGHIJKLMN_{t} | B11: [[['∅'], ['a']], [['B','C','D','E','F','G','H','I','J','K','L','M','N','O'], ['b','c','d','e','f','g','h','i','j','k','l','m','n']]] | C11: 0 | D11: 8.5821931 | E11: [[['∅'], ['m']], [['B', 'C', 'D', 'E', 'F', 'G', 'H', 'I', 'J', 'K', 'L', 'M', 'N', 'O'], ['a', 'b', 'c', 'd', 'e', 'f', 'g', 'h', 'i', 'j', 'k', 'l', 'n']]] | F11: 0 | G11: 0.94633245 | H11: [[['∅'],['m']],[['B','C','D','E','F','G','H','I','J','K','L','M','N','O'],['a','b','c','d','e','f','g','h','i','j','k','l','n']]] | I11: 0 | J11: 1.6832728 | K11: =IF('15A elementos'!$F11=0, IF('15A elementos'!$I11=0, 0, "Indefinido"), ABS('15A elementos'!$F11-'15A elementos'!$I11)/'15A elementos'!$F11) -> 0 | L11: 1 | M11: ='15A elementos'!$G11/'15A elementos'!$J11 -> 0.5621979
A12: BCDEFGHIJKLMNO_{t+1}|BCDEFGHIJKLMNO_{t} | B12: [[['∅'], ['b']], [['B','C','D','E','F','G','H','I','J','K','L','M','N','O'], ['c','d','e','f','g','h','i','j','k','l','m','n','o']]] | C12: 0 | D12: 9.036088 | E12: [[['∅'], ['o']], [['B', 'C', 'D', 'E', 'F', 'G', 'H', 'I', 'J', 'K', 'L', 'M', 'N', 'O'], ['b', 'c', 'd', 'e', 'f', 'g', 'h', 'i', 'j', 'k', 'l', 'm', 'n']]] | F12: 0 | G12: 0.42462492 | H12: [[['∅'],['o']],[['B','C','D','E','F','G','H','I','J','K','L','M','N','O'],['b','c','d','e','f','g','h','i','j','k','l','m','n']]] | I12: 0 | J12: 0.11944103 | K12: =IF('15A elementos'!$F12=0, IF('15A elementos'!$I12=0, 0, "Indefinido"), ABS('15A elementos'!$F12-'15A elementos'!$I12)/'15A elementos'!$F12) -> 0 | L12: 1 | M12: ='15A elementos'!$G12/'15A elementos'!$J12 -> 3.5551009
A13: BCDEFGHIJKLMN_{t+1}|ABCDEFGHIJKLMNO_{t} | B13: [[['∅'], ['a']], [['B','C','D','E','F','G','H','I','J','K','L','M','N'], ['b','c','d','e','f','g','h','i','j','k','l','m','n','o']]] | C13: 0 | D13: 3.4997115 | E13: [[['∅'], ['o']], [['B', 'C', 'D', 'E', 'F', 'G', 'H', 'I', 'J', 'K', 'L', 'M', 'N'], ['a', 'b', 'c', 'd', 'e', 'f', 'g', 'h', 'i', 'j', 'k', 'l', 'm', 'n']]] | F13: 0 | G13: 0.52708483 | H13: [[['∅'],['o']],[['B','C','D','E','F','G','H','I','J','K','L','M','N'],['a','b','c','d','e','f','g','h','i','j','k','l','m','n']]] | I13: 0 | J13: 1.8496244 | K13: =IF('15A elementos'!$F13=0, IF('15A elementos'!$I13=0, 0, "Indefinido"), ABS('15A elementos'!$F13-'15A elementos'!$I13)/'15A elementos'!$F13) -> 0 | L13: 1 | M13: ='15A elementos'!$G13/'15A elementos'!$J13 -> 0.28496857
A14: ABCDEFGHIJKLMN_{t+1}|BCDEFGHIJKLMN_{t} | B14: [[['∅'], ['b']], [['A','B','C','D','E','F','G','H','I','J','K','L','M','N'], ['c','d','e','f','g','h','i','j','k','l','m','n']]] | C14: 0 | D14: 10.115054 | E14: [[['∅'], ['g']], [['A', 'B', 'C', 'D', 'E', 'F', 'G', 'H', 'I', 'J', 'K', 'L', 'M', 'N'], ['b', 'c', 'd', 'e', 'f', 'h', 'i', 'j', 'k', 'l', 'm', 'n']]] | F14: 0 | G14: 0.69706297 | H14: [[['∅'],['g']],[['A','B','C','D','E','F','G','H','I','J','K','L','M','N'],['b','c','d','e','f','h','i','j','k','l','m','n']]] | I14: 0 | J14: 0.58417487 | K14: =IF('15A elementos'!$F14=0, IF('15A elementos'!$I14=0, 0, "Indefinido"), ABS('15A elementos'!$F14-'15A elementos'!$I14)/'15A elementos'!$F14) -> 0 | L14: 1 | M14: ='15A elementos'!$G14/'15A elementos'!$J14 -> 1.1932437
... A19: BCDEFGJKLMNO_{t+1}|BCDEFGHIJKLMNO_{t} | B19: [[['∅'], ['b']], [['B','C','D','E','F','G','J','K','L','M','N','O'], ['c','d','e','f','g','h','i','j','k','l','m','n','o']]] | C19: 0 | D19: 71.45602 | E19: [[['∅'], ['o']], [['B', 'C', 'D', 'E', 'F', 'G', 'J', 'K', 'L', 'M', 'N', 'O'], ['b', 'c', 'd', 'e', 'f', 'g', 'h', 'i', 'j', 'k', 'l', 'm', 'n']]] | F19: 0 | G19: 0.42889261 | H19: [[['∅'],['o']],[['B','C','D','E','F','G','J','K','L','M','N','O'],['b','c','d','e','f','g','h','i','j','k','l','m','n']]] | I19: 0 | J19: 1.6592803 | K19: =IF('15A elementos'!$F19=0, IF('15A elementos'!$I19=0, 0, "Indefinido"), ABS('15A elementos'!$F19-'15A elementos'!$I19)/'15A elementos'!$F19) -> 0 | L19: 1 | M19: ='15A elementos'!$G19/'15A elementos'!$J19 -> 0.25848111
A20: ABCDEFGHIJKLMNO_{t+1}|ABDEGHJKMN_{t} | E20: [[['O'], ['∅']], [['A', 'B', 'C', 'D', 'E', 'F', 'G', 'H', 'I', 'J', 'K', 'L', 'M', 'N'], ['a', 'b', 'd', 'e', 'g', 'h', 'j', 'k', 'm', 'n']]] | F20: 4.7147274e-05 | G20: 0.52439451 | H20: [[['O'],['∅']],[['A','B','C','D','E','F','G','H','I','J','K','L','M','N'],['a','b','e','g','j','k','n']]] | I20: 4.7147274e-05 | J20: 0.48621321 | K20: =IF('15A elementos'!$F20=0, IF('15A elementos'!$I20=0, 0, "Indefinido"), ABS('15A elementos'!$F20-'15A elementos'!$I20)/'15A elementos'!$F20) -> 4.3117638e-16 | L20: 1 | M20: ='15A elementos'!$G20/'15A elementos'!$J20 -> 1.0785279
A21: ABDEGHJKMN_{t+1}|ABCDEFGHIJKLMNO_{t} | B21: [[['∅'], ['a']], [['A','B','D','E','G','H','J','K','M','N'], ['b','c','d','e','f','g','h','i','j','k','l','m','n','o']]] | C21: 0 | D21: 9.7167048 | E21: [[['∅'], ['o']], [['A', 'B', 'D', 'E', 'G', 'H', 'J', 'K', 'M', 'N'], ['a', 'b', 'c', 'd', 'e', 'f', 'g', 'h', 'i', 'j', 'k', 'l', 'm', 'n']]] | F21: 0 | G21: 0.63509297 | H21: [[['∅'],['o']],[['A','B','D','E','G','H','J','K','M','N'],['a','b','c','d','e','f','g','h','i','j','k','l','m','n']]] | I21: 0 | J21: 1.7608535 | K21: =IF('15A elementos'!$F21=0, IF('15A elementos'!$I21=0, 0, "Indefinido"), ABS('15A elementos'!$F21-'15A elementos'!$I21)/'15A elementos'!$F21) -> 0 | L21: 1 | M21: ='15A elementos'!$G21/'15A elementos'!$J21 -> 0.36067337
A22: ABCDEFGHIJKLMN_{t+1}|ABDEGHJKMN_{t} | E22: [[['N'], ['∅']], [['A', 'B', 'C', 'D', 'E', 'F', 'G', 'H', 'I', 'J', 'K', 'L', 'M'], ['a', 'b', 'd', 'e', 'g', 'h', 'j', 'k', 'm', 'n']]] | F22: 0.0013378263 | G22: 0.18634677 | H22: [[['N'],['∅']],[['A','B','C','D','E','F','G','H','I','J','K','L','M'],['a','b','e','g','j','k','n']]] | I22: 0.0013378263 | J22: 0.49222517 | K22: =IF('15A elementos'!$F22=0, IF('15A elementos'!$I22=0, 0, "Indefinido"), ABS('15A elementos'!$F22-'15A elementos'!$I22)/'15A elementos'!$F22) -> 2.2691781e-15 | L22: 1 | M22: ='15A elementos'!$G22/'15A elementos'!$J22 -> 0.37858033
A23: BCDEFGHIJKLMNO_{t+1}|ABDEGHJKMN_{t} | E23: [[['O'], ['∅']], [['B', 'C', 'D', 'E', 'F', 'G', 'H', 'I', 'J', 'K', 'L', 'M', 'N'], ['a', 'b', 'd', 'e', 'g', 'h', 'j', 'k', 'm', 'n']]] | F23: 4.7147274e-05 | G23: 0.22196913 | H23: [[['O'],['∅']],[['B','C','D','E','F','G','H','I','J','K','L','M','N'],['a','b','e','g','j','k','n']]] | I23: 4.7147274e-05 | J23: 2.1477294 | K23: =IF('15A elementos'!$F23=0, IF('15A elementos'!$I23=0, 0, "Indefinido"), ABS('15A elementos'!$F23-'15A elementos'!$I23)/'15A elementos'!$F23) -> 4.3117638e-16 | L23: 1 | M23: ='15A elementos'!$G23/'15A elementos'!$J23 -> 0.1033506
A24: ABDEGHJKMN_{t+1}|ABCDEFGHIJKLMN_{t} | B24: [[['∅'], ['a']], [['A','B','D','E','G','H','J','K','M','N'], ['b','c','d','e','f','g','h','i','j','k','l','m','n']]] | C24: 0 | D24: 9.6454239 | E24: [[['∅'], ['g']], [['A', 'B', 'D', 'E', 'G', 'H', 'J', 'K', 'M', 'N'], ['a', 'b', 'c', 'd', 'e', 'f', 'h', 'i', 'j', 'k', 'l', 'm', 'n']]] | F24: 0 | G24: 0.52536273 | H24: [[['∅'],['m']],[['A','B','D','E','G','H','J','K','M','N'],['a','b','c','d','e','f','g','h','i','j','k','l','n']]] | I24: 0 | J24: 0.095818043 | K24: =IF('15A elementos'!$F24=0, IF('15A elementos'!$I24=0, 0, "Indefinido"), ABS('15A elementos'!$F24-'15A elementos'!$I24)/'15A elementos'!$F24) -> 0 | L24: 0 | M24: ='15A elementos'!$G24/'15A elementos'!$J24 -> 5.4829207
A25: ABDEGHJKMN_{t+1}|BCDEFGHIJKLMNO_{t} | B25: [[['∅'], ['b']], [['A','B','D','E','G','H','J','K','M','N'], ['c','d','e','f','g','h','i','j','k','l','m','n','o']]] | C25: 0 | D25: 10.052286 | E25: [[['∅'], ['o']], [['A', 'B', 'D', 'E', 'G', 'H', 'J', 'K', 'M', 'N'], ['b', 'c', 'd', 'e', 'f', 'g', 'h', 'i', 'j', 'k', 'l', 'm', 'n']]] | F25: 0 | G25: 0.38019419 | H25: [[['∅'],['o']],[['A','B','D','E','G','H','J','K','M','N'],['b','c','d','e','f','g','h','i','j','k','l','m','n']]] | I25: 0 | J25: 1.6353416 | K25: =IF('15A elementos'!$F25=0, IF('15A elementos'!$I25=0, 0, "Indefinido"), ABS('15A elementos'!$F25-'15A elementos'!$I25)/'15A elementos'!$F25) -> 0 | L25: 1 | M25: ='15A elementos'!$G25/'15A elementos'!$J25 -> 0.23248609
A26: ABCDEFGHIJKLMNO_{t+1}|ACEGIKMO_{t} | E26: [[['L'], ['∅']], [['A', 'B', 'C', 'D', 'E', 'F', 'G', 'H', 'I', 'J', 'K', 'M', 'N', 'O'], ['a', 'c', 'e', 'g', 'i', 'k', 'm', 'o']]] | F26: 0.0041897893 | G26: 0.34896326 | H26: [[['L'],['∅']],[['A','B','C','D','E','F','G','H','I','J','K','M','N','O'],['a','e','i','m']]] | I26: 0.0041897893 | J26: 0.47688818 | K26: =IF('15A elementos'!$F26=0, IF('15A elementos'!$I26=0, 0, "Indefinido"), ABS('15A elementos'!$F26-'15A elementos'!$I26)/'15A elementos'!$F26) -> 8.2807194e-16 | L26: 1 | M26: ='15A elementos'!$G26/'15A elementos'!$J26 -> 0.7317507
A27: BCDEFGHIJKLMN_{t+1}|ABDEGHJKMN_{t} | E27: [[['N'], ['∅']], [['B', 'C', 'D', 'E', 'F', 'G', 'H', 'I', 'J', 'K', 'L', 'M'], ['a', 'b', 'd', 'e', 'g', 'h', 'j', 'k', 'm', 'n']]] | F27: 0.0013378263 | G27: 0.16513538 | H27: [[['N'],['∅']],[['B','C','D','E','F','G','H','I','J','K','L','M'],['a','b','e','g','j','k','n']]] | I27: 0.0013378263 | J27: 0.51998758 | K27: =IF('15A elementos'!$F27=0, IF('15A elementos'!$I27=0, 0, "Indefinido"), ABS('15A elementos'!$F27-'15A elementos'!$I27)/'15A elementos'!$F27) -> 2.2691781e-15 | L27: 1 | M27: ='15A elementos'!$G27/'15A elementos'!$J27 -> 0.31757563
A28: ACEGIKMO_{t+1}|ABCDEFGHIJKLMNO_{t} | B28: [[['∅'], ['a']], [['A','C','E','G','I','K','M','O'], ['b','c','d','e','f','g','h','i','j','k','l','m','n','o']]] | C28: 0 | D28: 2.8380947 | E28: [[['∅'], ['i']], [['A', 'C', 'E', 'G', 'I', 'K', 'M', 'O'], ['a', 'b', 'c', 'd', 'e', 'f', 'g', 'h', 'j', 'k', 'l', 'm', 'n', 'o']]] | F28: 0 | G28: 0.23332548 | H28: [[['∅'],['o']],[['A','C','E','G','I','K','M','O'],['a','b','c','d','e','f','g','h','i','j','k','l','m','n']]] | I28: 0 | J28: 0.1774857 | K28: =IF('15A elementos'!$F28=0, IF('15A elementos'!$I28=0, 0, "Indefinido"), ABS('15A elementos'!$F28-'15A elementos'!$I28)/'15A elementos'!$F28) -> 0 | L28: 0 | M28: ='15A elementos'!$G28/'15A elementos'!$J28 -> 1.3146156
A29: ABDEGHJKMN_{t+1}|BCDEFGHIJKLMN_{t} | B29: [[['∅'], ['b']], [['A','B','D','E','G','H','J','K','M','N'], ['c','d','e','f','g','h','i','j','k','l','m','n']]] | C29: 0 | D29: 10.445736 | E29: [[['∅'], ['g']], [['A', 'B', 'D', 'E', 'G', 'H', 'J', 'K', 'M', 'N'], ['b', 'c', 'd', 'e', 'f', 'h', 'i', 'j', 'k', 'l', 'm', 'n']]] | F29: 0 | G29: 0.43327785 | H29: [[['∅'],['g']],[['A','B','D','E','G','H','J','K','M','N'],['b','c','d','e','f','h','i','j','k','l','m','n']]] | I29: 0 | J29: 0.5893929 | K29: =IF('15A elementos'!$F29=0, IF('15A elementos'!$I29=0, 0, "Indefinido"), ABS('15A elementos'!$F29-'15A elementos'!$I29)/'15A elementos'!$F29) -> 0 | L29: 1 | M29: ='15A elementos'!$G29/'15A elementos'!$J29 -> 0.73512566
A30: ABCDEFGHIJKLMNO_{t+1}|BDFHJLN_{t} | E30: [[['G'], ['∅']], [['A', 'B', 'C', 'D', 'E', 'F', 'H', 'I', 'J', 'K', 'L', 'M', 'N', 'O'], ['b', 'd', 'f', 'h', 'j', 'l', 'n']]] | F30: 0.0070973635 | G30: 0.3359859 | H30: [[['E'],['∅']],[['A','B','C','D','F','G','H','I','J','K','L','M','N','O'],['d','h','l']]] | I30: 0.0072056651 | J30: 0.4651382 | K30: =IF('15A elementos'!$F30=0, IF('15A elementos'!$I30=0, 0, "Indefinido"), ABS('15A elementos'!$F30-'15A elementos'!$I30)/'15A elementos'!$F30) -> 0.015259419 | L30: 0 | M30: ='15A elementos'!$G30/'15A elementos'!$J30 -> 0.72233564
A31: ABCDEFGHIJKLMN_{t+1}|ACEGIKMO_{t} | E31: [[['L'], ['∅']], [['A', 'B', 'C', 'D', 'E', 'F', 'G', 'H', 'I', 'J', 'K', 'M', 'N'], ['a', 'c', 'e', 'g', 'i', 'k', 'm', 'o']]] | F31: 0.0041897893 | G31: 0.19053721 | H31: [[['L'],['∅']],[['A','B','C','D','E','F','G','H','I','J','K','M','N'],['a','e','i','m']]] | I31: 0.0041897893 | J31: 0.50172043 | K31: =IF('15A elementos'!$F31=0, IF('15A elementos'!$I31=0, 0, "Indefinido"), ABS('15A elementos'!$F31-'15A elementos'!$I31)/'15A elementos'!$F31) -> 8.2807194e-16 | L31: 1 | M31: ='15A elementos'!$G31/'15A elementos'!$J31 -> 0.3797677
A32: BCDEFGHIJKLMNO_{t+1}|ACEGIKMO_{t} | E32: [[['L'], ['∅']], [['B', 'C', 'D', 'E', 'F', 'G', 'H', 'I', 'J', 'K', 'M', 'N', 'O'], ['a', 'c', 'e', 'g', 'i', 'k', 'm', 'o']]] | F32: 0.0041897893 | G32: 0.18016958 | H32: [[['L'],['∅']],[['B','C','D','E','F','G','H','I','J','K','M','N','O'],['a','e','i','m']]] | I32: 0.0041897893 | J32: 0.019664526 | K32: =IF('15A elementos'!$F32=0, IF('15A elementos'!$I32=0, 0, "Indefinido"), ABS('15A elementos'!$F32-'15A elementos'!$I32)/'15A elementos'!$F32) -> 8.2807194e-16 | L32: 0 | M32: ='15A elementos'!$G32/'15A elementos'!$J32 -> 9.1621625
A33: ACEGIKMO_{t+1}|ABCDEFGHIJKLMN_{t} | B33: [[['∅'], ['a']], [['A','C','E','G','I','K','M','O'], ['b','c','d','e','f','g','h','i','j','k','l','m','n']]] | C33: 0 | D33: 2.8799107 | E33: [[['∅'], ['g']], [['A', 'C', 'E', 'G', 'I', 'K', 'M', 'O'], ['a', 'b', 'c', 'd', 'e', 'f', 'h', 'i', 'j', 'k', 'l', 'm', 'n']]] | F33: 0 | G33: 0.55452061 | H33: [[['∅'],['m']],[['A','C','E','G','I','K','M','O'],['a','b','c','d','e','f','g','h','i','j','k','l','n']]] | I33: 0 | J33: 0.089427948 | K33: =IF('15A elementos'!$F33=0, IF('15A elementos'!$I33=0, 0, "Indefinido"), ABS('15A elementos'!$F33-'15A elementos'!$I33)/'15A elementos'!$F33) -> 0 | L33: 1 | M33: ='15A elementos'!$G33/'15A elementos'!$J33 -> 6.2007529
A34: ACEGIKMO_{t+1}|BCDEFGHIJKLMNO_{t} | B34: [[['∅'], ['b']], [['A','C','E','G','I','K','M','O'], ['c','d','e','f','g','h','i','j','k','l','m','n','o']]] | C34: 0 | D34: 3.0614157 | E34: [[['∅'], ['o']], [['A', 'C', 'E', 'G', 'I', 'K', 'M', 'O'], ['b', 'c', 'd', 'e', 'f', 'g', 'h', 'i', 'j', 'k', 'l', 'm', 'n']]] | F34: 0 | G34: 0.32070971 | H34: [[['∅'],['o']],[['A','C','E','G','I','K','M','O'],['b','c','d','e','f','g','h','i','j','k','l','m','n']]] | I34: 0 | J34: 0.09041357 | K34: =IF('15A elementos'!$F34=0, IF('15A elementos'!$I34=0, 0, "Indefinido"), ABS('15A elementos'!$F34-'15A elementos'!$I34)/'15A elementos'!$F34) -> 0 | L34: 0 | M34: ='15A elementos'!$G34/'15A elementos'!$J34 -> 3.5471413
A35: BDFHJLN_{t+1}|ABCDEFGHIJKLMNO_{t} | B35: [[['∅'], ['a']], [['B','D','F','H','J','L','N'], ['b','c','d','e','f','g','h','i','j','k','l','m','n','o']]] | C35: 0 | D35: 2.5502007 | E35: [[['∅'], ['i']], [['B', 'D', 'F', 'H', 'J', 'L', 'N'], ['a', 'b', 'c', 'd', 'e', 'f', 'g', 'h', 'j', 'k', 'l', 'm', 'n', 'o']]] | F35: 0 | G35: 0.18429708 | H35: [[['∅'],['o']],[['B','D','F','H','J','L','N'],['a','b','c','d','e','f','g','h','i','j','k','l','m','n']]] | I35: 0 | J35: 0.16971087 | K35: =IF('15A elementos'!$F35=0, IF('15A elementos'!$I35=0, 0, "Indefinido"), ABS('15A elementos'!$F35-'15A elementos'!$I35)/'15A elementos'!$F35) -> 0 | L35: 0 | M35: ='15A elementos'!$G35/'15A elementos'!$J35 -> 1.0859474
A36: ABCDEFGHIJKLMN_{t+1}|BDFHJLN_{t} | E36: [[['G'], ['∅']], [['A', 'B', 'C', 'D', 'E', 'F', 'H', 'I', 'J', 'K', 'L', 'M', 'N'], ['b', 'd', 'f', 'h', 'j', 'l', 'n']]] | F36: 0.0070973635 | G36: 0.1929009 | H36: [[['E'],['∅']],[['A','B','C','D','F','G','H','I','J','K','L','M','N'],['d','h','l']]] | I36: 0.0072056651 | J36: 0.37964702 | K36: =IF('15A elementos'!$F36=0, IF('15A elementos'!$I36=0, 0, "Indefinido"), ABS('15A elementos'!$F36-'15A elementos'!$I36)/'15A elementos'!$F36) -> 0.015259419 | L36: 0 | M36: ='15A elementos'!$G36/'15A elementos'!$J36 -> 0.50810592
A37: BCDEFGHIJKLMNO_{t+1}|BDFHJLN_{t} | E37: [[['G'], ['∅']], [['B', 'C', 'D', 'E', 'F', 'H', 'I', 'J', 'K', 'L', 'M', 'N', 'O'], ['b', 'd', 'f', 'h', 'j', 'l', 'n']]] | F37: 0.0070973635 | G37: 0.19927883 | H37: [[['E'],['∅']],[['B','C','D','F','G','H','I','J','K','L','M','N','O'],['d','h','l']]] | I37: 0.0072056651 | J37: 0.5145514 | K37: =IF('15A elementos'!$F37=0, IF('15A elementos'!$I37=0, 0, "Indefinido"), ABS('15A elementos'!$F37-'15A elementos'!$I37)/'15A elementos'!$F37) -> 0.015259419 | L37: 1 | M37: ='15A elementos'!$G37/'15A elementos'!$J37 -> 0.38728654
A38: BCDEFGHIJKLMN_{t+1}|ACEGIKMO_{t} | E38: [[['L'], ['∅']], [['B', 'C', 'D', 'E', 'F', 'G', 'H', 'I', 'J', 'K', 'M', 'N'], ['a', 'c', 'e', 'g', 'i', 'k', 'm', 'o']]] | F38: 0.0041897893 | G38: 0.16062665 | H38: [[['L'],['∅']],[['B','C','D','E','F','G','H','I','J','K','M','N'],['a','e','i','m']]] | I38: 0.0041897893 | J38: 0.35796595 | K38: =IF('15A elementos'!$F38=0, IF('15A elementos'!$I38=0, 0, "Indefinido"), ABS('15A elementos'!$F38-'15A elementos'!$I38)/'15A elementos'!$F38) -> 8.2807194e-16 | L38: 1 | M38: ='15A elementos'!$G38/'15A elementos'!$J38 -> 0.44872048
A39: ACEGIKMO_{t+1}|BCDEFGHIJKLMN_{t} | B39: [[['∅'], ['b']], [['A','C','E','G','I','K','M','O'], ['c','d','e','f','g','h','i','j','k','l','m','n']]] | C39: 0 | D39: 3.1781836 | E39: [[['∅'], ['g']], [['A', 'C', 'E', 'G', 'I', 'K', 'M', 'O'], ['b', 'c', 'd', 'e', 'f', 'h', 'i', 'j', 'k', 'l', 'm', 'n']]] | F39: 0 | G39: 0.33545589 | H39: [[['∅'],['g']],[['A','C','E','G','I','K','M','O'],['b','c','d','e','f','h','i','j','k','l','m','n']]] | I39: 0 | J39: 0.5790379 | K39: =IF('15A elementos'!$F39=0, IF('15A elementos'!$I39=0, 0, "Indefinido"), ABS('15A elementos'!$F39-'15A elementos'!$I39)/'15A elementos'!$F39) -> 0 | L39: 0 | M39: ='15A elementos'!$G39/'15A elementos'!$J39 -> 0.57933322
A40: BDFHJLN_{t+1}|ABCDEFGHIJKLMN_{t} | B40: [[['∅'], ['a']], [['B','D','F','H','J','L','N'], ['b','c','d','e','f','g','h','i','j','k','l','m','n']]] | C40: 0 | D40: 2.7478979 | E40: [[['∅'], ['g']], [['B', 'D', 'F', 'H', 'J', 'L', 'N'], ['a', 'b', 'c', 'd', 'e', 'f', 'h', 'i', 'j', 'k', 'l', 'm', 'n']]] | F40: 0 | G40: 0.36375523 | H40: [[['∅'],['m']],[['B','D','F','H','J','L','N'],['a','b','c','d','e','f','g','h','i','j','k','l','n']]] | I40: 0 | J40: 0.078887463 | K40: =IF('15A elementos'!$F40=0, IF('15A elementos'!$I40=0, 0, "Indefinido"), ABS('15A elementos'!$F40-'15A elementos'!$I40)/'15A elementos'!$F40) -> 0 | L40: 0 | M40: ='15A elementos'!$G40/'15A elementos'!$J40 -> 4.6110651
A41: BDFHJLN_{t+1}|BCDEFGHIJKLMNO_{t} | B41: [[['∅'], ['b']], [['B','D','F','H','J','L','N'], ['c','d','e','f','g','h','i','j','k','l','m','n','o']]] | C41: 0 | D41: 2.6484423 | E41: [[['∅'], ['o']], [['B', 'D', 'F', 'H', 'J', 'L', 'N'], ['b', 'c', 'd', 'e', 'f', 'g', 'h', 'i', 'j', 'k', 'l', 'm', 'n']]] | F41: 0 | G41: 0.20614672 | H41: [[['∅'],['o']],[['B','D','F','H','J','L','N'],['b','c','d','e','f','g','h','i','j','k','l','m','n']]] | I41: 0 | J41: 0.081706047 | K41: =IF('15A elementos'!$F41=0, IF('15A elementos'!$I41=0, 0, "Indefinido"), ABS('15A elementos'!$F41-'15A elementos'!$I41)/'15A elementos'!$F41) -> 0 | L41: 1 | M41: ='15A elementos'!$G41/'15A elementos'!$J41 -> 2.5230289
A42: BCDEFGHIJKLMN_{t+1}|BDFHJLN_{t} | E42: [[['G'], ['∅']], [['B', 'C', 'D', 'E', 'F', 'H', 'I', 'J', 'K', 'L', 'M', 'N'], ['b', 'd', 'f', 'h', 'j', 'l', 'n']]] | F42: 0.0070973635 | G42: 0.14544654 | H42: [[['E'],['∅']],[['B','C','D','F','G','H','I','J','K','L','M','N'],['d','h','l']]] | I42: 0.0072056651 | J42: 0.45584035 | K42: =IF('15A elementos'!$F42=0, IF('15A elementos'!$I42=0, 0, "Indefinido"), ABS('15A elementos'!$F42-'15A elementos'!$I42)/'15A elementos'!$F42) -> 0.015259419 | L42: 1 | M42: ='15A elementos'!$G42/'15A elementos'!$J42 -> 0.31907342
A43: BDFHJLN_{t+1}|BCDEFGHIJKLMN_{t} | B43: [[['∅'], ['b']], [['B','D','F','H','J','L','N'], ['c','d','e','f','g','h','i','j','k','l','m','n']]] | C43: 0 | D43: 3.1360073 | E43: [[['∅'], ['g']], [['B', 'D', 'F', 'H', 'J', 'L', 'N'], ['b', 'c', 'd', 'e', 'f', 'h', 'i', 'j', 'k', 'l', 'm', 'n']]] | F43: 0 | G43: 0.28363752 | H43: [[['∅'],['g']],[['B','D','F','H','J','L','N'],['b','c','d','e','f','h','i','j','k','l','m','n']]] | I43: 0 | J43: 0.075541735 | K43: =IF('15A elementos'!$F43=0, IF('15A elementos'!$I43=0, 0, "Indefinido"), ABS('15A elementos'!$F43-'15A elementos'!$I43)/'15A elementos'!$F43) -> 0 | L43: 1 | M43: ='15A elementos'!$G43/'15A elementos'!$J43 -> 3.7547129
A44: ABDEGHJKMN_{t+1}|ABDEGHJKMN_{t} | B44: [[['N'], ['∅']], [['A','B','D','E','G','H','J','K','M'], ['a','b','d','e','g','h','j','k','m','n']]] | C44: 0.001338 | D44: 129.84961 | E44: [[['N'], ['∅']], [['A', 'B', 'D', 'E', 'G', 'H', 'J', 'K', 'M'], ['a', 'b', 'd', 'e', 'g', 'h', 'j', 'k', 'm', 'n']]] | F44: 0.0013378263 | G44: 0.21704936 | H44: [[['N'],['∅']],[['A','B','D','E','G','H','J','K','M'],['a','b','e','g','j','k','n']]] | I44: 0.0013378263 | J44: 0.47032547 | K44: =IF('15A elementos'!$F44=0, IF('15A elementos'!$I44=0, 0, "Indefinido"), ABS('15A elementos'!$F44-'15A elementos'!$I44)/'15A elementos'!$F44) -> 2.2691781e-15 | L44: 1 | M44: ='15A elementos'!$G44/'15A elementos'!$J44 -> 0.46148757
...

Sheet 15B elementos
B1: Resultados Pyphi | E1: EstrategiaQ | H1: GeoMIP | K1: Analisis de error y precision | M1: rendimiento temporal
A2: Subsistema | B2: Particion | C2: Perdida | D2: Tiempo | E2: Particion5 | F2: Perdida6 | G2: Tiempo7 | H2: Particion5 | I2: Perdida6 | J2: Tiempo ejecución | K2: error relativo | L2: tasa de acierto2 | M2: speedup
A3: ABCDEFGHIJKLMNO_{t+1}|ABCDEFGHIJKLMNO_{t} | B3: [[['∅'], ['a']], [['A', 'B', 'C', 'D', 'E', 'F', 'G', 'H', 'I', 'J', 'K', 'L', 'M', 'N', 'O'], ['b', 'c', 'd', 'e', 'f', 'g', 'h', 'i', 'j', 'k', 'l', 'm', 'n', 'o']]] | C3: 0 | D3: 34.428434 | E3: [[['∅'], ['o']], [['A', 'B', 'C', 'D', 'E', 'F', 'G', 'H', 'I', 'J', 'K', 'L', 'M', 'N', 'O'], ['a', 'b', 'c', 'd', 'e', 'f', 'g', 'h', 'i', 'j', 'k', 'l', 'm', 'n']]] | F3: 0 | G3: 2.8741245 | H3: [[['∅'],['o']],[['A','B','C','D','E','F','G','H','I','J','K','L','M','N','O'],['a','b','c','d','e','f','g','h','i','j','k','l','m','n']]] | I3: 0 | J3: 1.8886199 | K3: =IF('15B elementos'!$F3=0, IF('15B elementos'!$I3=0, 0, "Indefinido"), ABS('15B elementos'!$F3-'15B elementos'!$I3)/'15B elementos'!$F3) -> 0 | L3: 1 | M3: ='15B elementos'!$G3/'15B elementos'!$J3 -> 1.5218121
A4: ABCDEFGHIJKLMNO_{t+1}|ABCDEFGHIJKLMN_{t} | B4: [[['∅'], ['a']], [['A', 'B', 'C', 'D', 'E', 'F', 'G', 'H', 'I', 'J', 'K', 'L', 'M', 'N', 'O'], ['b', 'c', 'd', 'e', 'f', 'g', 'h', 'i', 'j', 'k', 'l', 'm', 'n']]] | C4: 0 | D4: 47.741694 | E4: [[['∅'], ['l']], [['A', 'B', 'C', 'D', 'E', 'F', 'G', 'H', 'I', 'J', 'K', 'L', 'M', 'N', 'O'], ['a', 'b', 'c', 'd', 'e', 'f', 'g', 'h', 'i', 'j', 'k', 'm', 'n']]] | F4: 0 | G4: 1.763633 | H4: [[['∅'],['m']],[['A','B','C','D','E','F','G','H','I','J','K','L','M','N','O'],['a','b','c','d','e','f','g','h','i','j','k','l','n']]] | I4: 0 | J4: 0.11499238 | K4: =IF('15B elementos'!$F4=0, IF('15B elementos'!$I4=0, 0, "Indefinido"), ABS('15B elementos'!$F4-'15B elementos'!$I4)/'15B elementos'!$F4) -> 0 | L4: 0 | M4: ='15B elementos'!$G4/'15B elementos'!$J4 -> 15.336955
A5: ABCDEFGHIJKLMNO_{t+1}|BCDEFGHIJKLMNO_{t} | B5: [[['∅'], ['b']], [['A', 'B', 'C', 'D', 'E', 'F', 'G', 'H', 'I', 'J', 'K', 'L', 'M', 'N', 'O'], ['c', 'd', 'e', 'f', 'g', 'h', 'i', 'j', 'k', 'l', 'm', 'n', 'o']]] | C5: 0 | D5: 87.462926 | E5: [[['∅'], ['o']], [['A', 'B', 'C', 'D', 'E', 'F', 'G', 'H', 'I', 'J', 'K', 'L', 'M', 'N', 'O'], ['b', 'c', 'd', 'e', 'f', 'g', 'h', 'i', 'j', 'k', 'l', 'm', 'n']]] | F5: 0 | G5: 1.1910405 | H5: [[['∅'],['o']],[['A','B','C','D','E','F','G','H','I','J','K','L','M','N','O'],['b','c','d','e','f','g','h','i','j','k','l','m','n']]] | I5: 0 | J5: 1.6970785 | K5: =IF('15B elementos'!$F5=0, IF('15B elementos'!$I5=0, 0, "Indefinido"), ABS('15B elementos'!$F5-'15B elementos'!$I5)/'15B elementos'!$F5) -> 0 | L5: 1 | M5: ='15B elementos'!$G5/'15B elementos'!$J5 -> 0.70181818
A6: ABCDEFGHIJKLMN_{t+1}|ABCDEFGHIJKLMNO_{t} | B6: [[['∅'], ['a']], [['A', 'B', 'C', 'D', 'E', 'F', 'G', 'H', 'I', 'J', 'K', 'L', 'M', 'N'], ['b', 'c', 'd', 'e', 'f', 'g', 'h', 'i', 'j', 'k', 'l', 'm', 'n', 'o']]] | C6: 0 | D6: 10.973039 | E6: [[['∅'], ['o']], [['A', 'B', 'C', 'D', 'E', 'F', 'G', 'H', 'I', 'J', 'K', 'L', 'M', 'N'], ['a', 'b', 'c', 'd', 'e', 'f', 'g', 'h', 'i', 'j', 'k', 'l', 'm', 'n']]] | F6: 0 | G6: 0.43097782 | H6: [[['∅'],['o']],[['A','B','C','D','E','F','G','H','I','J','K','L','M','N'],['a','b','c','d','e','f','g','h','i','j','k','l','m','n']]] | I6: 0 | J6: 0.23936653 | K6: =IF('15B elementos'!$F6=0, IF('15B elementos'!$I6=0, 0, "Indefinido"), ABS('15B elementos'!$F6-'15B elementos'!$I6)/'15B elementos'!$F6) -> 0 | L6: 1 | M6: ='15B elementos'!$G6/'15B elementos'!$J6 -> 1.8004932
A7: BCDEFGHIJKLMNO_{t+1}|ABCDEFGHIJKLMNO_{t} | B7: [[['∅'], ['a']], [['B', 'C', 'D', 'E', 'F', 'G', 'H', 'I', 'J', 'K', 'L', 'M', 'N', 'O'], ['b', 'c', 'd', 'e', 'f', 'g', 'h', 'i', 'j', 'k', 'l', 'm', 'n', 'o']]] | C7: 0 | D7: 82.683896 | E7: [[['∅'], ['o']], [['B', 'C', 'D', 'E', 'F', 'G', 'H', 'I', 'J', 'K', 'L', 'M', 'N', 'O'], ['a', 'b', 'c', 'd', 'e', 'f', 'g', 'h', 'i', 'j', 'k', 'l', 'm', 'n']]] | F7: 0 | G7: 0.50125217 | H7: [[['∅'],['o']],[['B','C','D','E','F','G','H','I','J','K','L','M','N','O'],['a','b','c','d','e','f','g','h','i','j','k','l','m','n']]] | I7: 0 | J7: 1.9122262 | K7: =IF('15B elementos'!$F7=0, IF('15B elementos'!$I7=0, 0, "Indefinido"), ABS('15B elementos'!$F7-'15B elementos'!$I7)/'15B elementos'!$F7) -> 0 | L7: 1 | M7: ='15B elementos'!$G7/'15B elementos'!$J7 -> 0.26213017
A8: ABCDEFGHIJKLMNO_{t+1}|BCDEFGHIJKLMN_{t} | B8: [[['∅'], ['b']], [['A', 'B', 'C', 'D', 'E', 'F', 'G', 'H', 'I', 'J', 'K', 'L', 'M', 'N', 'O'], ['c', 'd', 'e', 'f', 'g', 'h', 'i', 'j', 'k', 'l', 'm', 'n']]] | C8: 0 | D8: 117.27852 | E8: [[['∅'], ['n']], [['A', 'B', 'C', 'D', 'E', 'F', 'G', 'H', 'I', 'J', 'K', 'L', 'M', 'N', 'O'], ['b', 'c', 'd', 'e', 'f', 'g', 'h', 'i', 'j', 'k', 'l', 'm']]] | F8: 0 | G8: 1.0145364 | H8: [[['∅'],['g']],[['A','B','C','D','E','F','G','H','I','J','K','L','M','N','O'],['b','c','d','e','f','h','i','j','k','l','m','n']]] | I8: 0 | J8: 0.58646607 | K8: =IF('15B elementos'!$F8=0, IF('15B elementos'!$I8=0, 0, "Indefinido"), ABS('15B elementos'!$F8-'15B elementos'!$I8)/'15B elementos'!$F8) -> 0 | L8: 0 | M8: ='15B elementos'!$G8/'15B elementos'!$J8 -> 1.7299149
A9: ABCDEFGHIJKLMN_{t+1}|ABCDEFGHIJKLMN_{t} | B9: [[['∅'], ['a']], [['A', 'B', 'C', 'D', 'E', 'F', 'G', 'H', 'I', 'J', 'K', 'L', 'M', 'N'], ['b', 'c', 'd', 'e', 'f', 'g', 'h', 'i', 'j', 'k', 'l', 'm', 'n']]] | C9: 0 | D9: 11.723634 | E9: [[['∅'], ['l']], [['A', 'B', 'C', 'D', 'E', 'F', 'G', 'H', 'I', 'J', 'K', 'L', 'M', 'N'], ['a', 'b', 'c', 'd', 'e', 'f', 'g', 'h', 'i', 'j', 'k', 'm', 'n']]] | F9: 0 | G9: 0.45981932 | H9: [[['∅'],['m']],[['A','B','C','D','E','F','G','H','I','J','K','L','M','N'],['a','b','c','d','e','f','g','h','i','j','k','l','n']]] | I9: 0 | J9: 1.7541485 | K9: =IF('15B elementos'!$F9=0, IF('15B elementos'!$I9=0, 0, "Indefinido"), ABS('15B elementos'!$F9-'15B elementos'!$I9)/'15B elementos'!$F9) -> 0 | L9: 0 | M9: ='15B elementos'!$G9/'15B elementos'!$J9 -> 0.26213249
A10: ABCDEFGHIJKLMN_{t+1}|BCDEFGHIJKLMNO_{t} | B10: [[['∅'], ['b']], [['A', 'B', 'C', 'D', 'E', 'F', 'G', 'H', 'I', 'J', 'K', 'L', 'M', 'N'], ['c', 'd', 'e', 'f', 'g', 'h', 'i', 'j', 'k', 'l', 'm', 'n', 'o']]] | C10: 0 | D10: 12.985172 | E10: [[['∅'], ['m']], [['A', 'B', 'C', 'D', 'E', 'F', 'G', 'H', 'I', 'J', 'K', 'L', 'M', 'N'], ['b', 'c', 'd', 'e', 'f', 'g', 'h', 'i', 'j', 'k', 'l', 'n', 'o']]] | F10: 0 | G10: 0.67040944 | H10: [[['∅'],['o']],[['A','B','C','D','E','F','G','H','I','J','K','L','M','N'],['b','c','d','e','f','g','h','i','j','k','l','m','n']]] | I10: 0 | J10: 0.11715221 | K10: =IF('15B elementos'!$F10=0, IF('15B elementos'!$I10=0, 0, "Indefinido"), ABS('15B elementos'!$F10-'15B elementos'!$I10)/'15B elementos'!$F10) -> 0 | L10: 0 | M10: ='15B elementos'!$G10/'15B elementos'!$J10 -> 5.7225503
A11: BCDEFGHIJKLMNO_{t+1}|ABCDEFGHIJKLMN_{t} | B11: [[['∅'], ['a']], [['B', 'C', 'D', 'E', 'F', 'G', 'H', 'I', 'J', 'K', 'L', 'M', 'N', 'O'], ['b', 'c', 'd', 'e', 'f', 'g', 'h', 'i', 'j', 'k', 'l', 'm', 'n']]] | C11: 0 | D11: 116.12531 | E11: [[['∅'], ['l']], [['B', 'C', 'D', 'E', 'F', 'G', 'H', 'I', 'J', 'K', 'L', 'M', 'N', 'O'], ['a', 'b', 'c', 'd', 'e', 'f', 'g', 'h', 'i', 'j', 'k', 'm', 'n']]] | F11: 0 | G11: 0.42214394 | H11: [[['∅'],['m']],[['B','C','D','E','F','G','H','I','J','K','L','M','N','O'],['a','b','c','d','e','f','g','h','i','j','k','l','n']]] | I11: 0 | J11: 1.6832728 | K11: =IF('15B elementos'!$F11=0, IF('15B elementos'!$I11=0, 0, "Indefinido"), ABS('15B elementos'!$F11-'15B elementos'!$I11)/'15B elementos'!$F11) -> 0 | L11: 0 | M11: ='15B elementos'!$G11/'15B elementos'!$J11 -> 0.25078759
A12: BCDEFGHIJKLMNO_{t+1}|BCDEFGHIJKLMNO_{t} | B12: [[['∅'], ['b']], [['B', 'C', 'D', 'E', 'F', 'G', 'H', 'I', 'J', 'K', 'L', 'M', 'N', 'O'], ['c', 'd', 'e', 'f', 'g', 'h', 'i', 'j', 'k', 'l', 'm', 'n', 'o']]] | C12: 0 | D12: 138.62408 | E12: [[['∅'], ['n']], [['B', 'C', 'D', 'E', 'F', 'G', 'H', 'I', 'J', 'K', 'L', 'M', 'N', 'O'], ['b', 'c', 'd', 'e', 'f', 'g', 'h', 'i', 'j', 'k', 'l', 'm', 'o']]] | F12: 0 | G12: 0.47676158 | H12: [[['∅'],['o']],[['B','C','D','E','F','G','H','I','J','K','L','M','N','O'],['b','c','d','e','f','g','h','i','j','k','l','m','n']]] | I12: 0 | J12: 0.11944103 | K12: =IF('15B elementos'!$F12=0, IF('15B elementos'!$I12=0, 0, "Indefinido"), ABS('15B elementos'!$F12-'15B elementos'!$I12)/'15B elementos'!$F12) -> 0 | L12: 0 | M12: ='15B elementos'!$G12/'15B elementos'!$J12 -> 3.9916063
A13: BCDEFGHIJKLMN_{t+1}|ABCDEFGHIJKLMNO_{t} | B13: [[['∅'], ['a']], [['B', 'C', 'D', 'E', 'F', 'G', 'H', 'I', 'J', 'K', 'L', 'M', 'N'], ['b', 'c', 'd', 'e', 'f', 'g', 'h', 'i', 'j', 'k', 'l', 'm', 'n', 'o']]] | C13: 0 | D13: 11.07549 | E13: [[['∅'], ['o']], [['B', 'C', 'D', 'E', 'F', 'G', 'H', 'I', 'J', 'K', 'L', 'M', 'N'], ['a', 'b', 'c', 'd', 'e', 'f', 'g', 'h', 'i', 'j', 'k', 'l', 'm', 'n']]] | F13: 0 | G13: 0.38063312 | H13: [[['∅'],['o']],[['B','C','D','E','F','G','H','I','J','K','L','M','N'],['a','b','c','d','e','f','g','h','i','j','k','l','m','n']]] | I13: 0 | J13: 1.8496244 | K13: =IF('15B elementos'!$F13=0, IF('15B elementos'!$I13=0, 0, "Indefinido"), ABS('15B elementos'!$F13-'15B elementos'!$I13)/'15B elementos'!$F13) -> 0 | L13: 1 | M13: ='15B elementos'!$G13/'15B elementos'!$J13 -> 0.20578941
A14: ABCDEFGHIJKLMN_{t+1}|BCDEFGHIJKLMN_{t} | B14: [[['∅'], ['b']], [['A', 'B', 'C', 'D', 'E', 'F', 'G', 'H', 'I', 'J', 'K', 'L', 'M', 'N'], ['c', 'd', 'e', 'f', 'g', 'h', 'i', 'j', 'k', 'l', 'm', 'n']]] | C14: 0 | D14: 13.975117 | E14: [[['∅'], ['n']], [['A', 'B', 'C', 'D', 'E', 'F', 'G', 'H', 'I', 'J', 'K', 'L', 'M', 'N'], ['b', 'c', 'd', 'e', 'f', 'g', 'h', 'i', 'j', 'k', 'l', 'm']]] | F14: 0 | G14: 0.40865302 | H14: [[['∅'],['g']],[['A','B','C','D','E','F','G','H','I','J','K','L','M','N'],['b','c','d','e','f','h','i','j','k','l','m','n']]] | I14: 0 | J14: 0.58417487 | K14: =IF('15B elementos'!$F14=0, IF('15B elementos'!$I14=0, 0, "Indefinido"), ABS('15B elementos'!$F14-'15B elementos'!$I14)/'15B elementos'!$F14) -> 0 | L14: 0 | M14: ='15B elementos'!$G14/'15B elementos'!$J14 -> 0.69953886
... A19: BCDEFGJKLMNO_{t+1}|BCDEFGHIJKLMNO_{t} | B19: [[['∅'], ['b']], [['B', 'C', 'D', 'E', 'F', 'G', 'J', 'K', 'L', 'M', 'N', 'O'], ['c', 'd', 'e', 'f', 'g', 'h', 'i', 'j', 'k', 'l', 'm', 'n', 'o']]] | C19: 0 | D19: 2.0651617 | E19: [[['∅'], ['m']], [['B', 'C', 'D', 'E', 'F', 'G', 'J', 'K', 'L', 'M', 'N', 'O'], ['b', 'c', 'd', 'e', 'f', 'g', 'h', 'i', 'j', 'k', 'l', 'n', 'o']]] | F19: 0 | G19: 0.33267546 | H19: [[['∅'],['o']],[['B','C','D','E','F','G','J','K','L','M','N','O'],['b','c','d','e','f','g','h','i','j','k','l','m','n']]] | I19: 0 | J19: 1.6592803 | K19: =IF('15B elementos'!$F19=0, IF('15B elementos'!$I19=0, 0, "Indefinido"), ABS('15B elementos'!$F19-'15B elementos'!$I19)/'15B elementos'!$F19) -> 0 | L19: 0 | M19: ='15B elementos'!$G19/'15B elementos'!$J19 -> 0.20049383
A20: ABCDEFGHIJKLMNO_{t+1}|ABDEGHJKMN_{t} | E20: [[['D'], ['∅']], [['A', 'B', 'C', 'E', 'F', 'G', 'H', 'I', 'J', 'K', 'L', 'M', 'N', 'O'], ['a', 'b', 'd', 'e', 'g', 'h', 'j', 'k', 'm', 'n']]] | F20: 0.00076055527 | G20: 0.50369191 | H20: [[['O'],['∅']],[['A','B','C','D','E','F','G','H','I','J','K','L','M','N'],['a','b','e','g','j','k','n']]] | I20: 4.7147274e-05 | J20: 0.48621321 | K20: =IF('15B elementos'!$F20=0, IF('15B elementos'!$I20=0, 0, "Indefinido"), ABS('15B elementos'!$F20-'15B elementos'!$I20)/'15B elementos'!$F20) -> 0.9380094 | L20: 0 | M20: ='15B elementos'!$G20/'15B elementos'!$J20 -> 1.0359486
A21: ABDEGHJKMN_{t+1}|ABCDEFGHIJKLMNO_{t} | B21: [[['∅'], ['a']], [['A', 'B', 'D', 'E', 'G', 'H', 'J', 'K', 'M', 'N'], ['b', 'c', 'd', 'e', 'f', 'g', 'h', 'i', 'j', 'k', 'l', 'm', 'n', 'o']]] | C21: 0 | D21: 1.0048969 | E21: [[['∅'], ['n']], [['A', 'B', 'D', 'E', 'G', 'H', 'J', 'K', 'M', 'N'], ['a', 'b', 'c', 'd', 'e', 'f', 'g', 'h', 'i', 'j', 'k', 'l', 'm', 'o']]] | F21: 0 | G21: 0.88586402 | H21: [[['∅'],['o']],[['A','B','D','E','G','H','J','K','M','N'],['a','b','c','d','e','f','g','h','i','j','k','l','m','n']]] | I21: 0 | J21: 1.7608535 | K21: =IF('15B elementos'!$F21=0, IF('15B elementos'!$I21=0, 0, "Indefinido"), ABS('15B elementos'!$F21-'15B elementos'!$I21)/'15B elementos'!$F21) -> 0 | L21: 0 | M21: ='15B elementos'!$G21/'15B elementos'!$J21 -> 0.50308785
A22: ABCDEFGHIJKLMN_{t+1}|ABDEGHJKMN_{t} | E22: [[['D'], ['∅']], [['A', 'B', 'C', 'E', 'F', 'G', 'H', 'I', 'J', 'K', 'L', 'M', 'N'], ['a', 'b', 'd', 'e', 'g', 'h', 'j', 'k', 'm', 'n']]] | F22: 0.00076055527 | G22: 0.26035523 | H22: [[['N'],['∅']],[['A','B','C','D','E','F','G','H','I','J','K','L','M'],['a','b','e','g','j','k','n']]] | I22: 0.0013378263 | J22: 0.49222517 | K22: =IF('15B elementos'!$F22=0, IF('15B elementos'!$I22=0, 0, "Indefinido"), ABS('15B elementos'!$F22-'15B elementos'!$I22)/'15B elementos'!$F22) -> 0.75901254 | L22: 0 | M22: ='15B elementos'!$G22/'15B elementos'!$J22 -> 0.52893523
A23: BCDEFGHIJKLMNO_{t+1}|ABDEGHJKMN_{t} | E23: [[['D'], ['∅']], [['B', 'C', 'E', 'F', 'G', 'H', 'I', 'J', 'K', 'L', 'M', 'N', 'O'], ['a', 'b', 'd', 'e', 'g', 'h', 'j', 'k', 'm', 'n']]] | F23: 0.00076055527 | G23: 0.23150015 | H23: [[['O'],['∅']],[['B','C','D','E','F','G','H','I','J','K','L','M','N'],['a','b','e','g','j','k','n']]] | I23: 4.7147274e-05 | J23: 2.1477294 | K23: =IF('15B elementos'!$F23=0, IF('15B elementos'!$I23=0, 0, "Indefinido"), ABS('15B elementos'!$F23-'15B elementos'!$I23)/'15B elementos'!$F23) -> 0.9380094 | L23: 0 | M23: ='15B elementos'!$G23/'15B elementos'!$J23 -> 0.10778832
A24: ABDEGHJKMN_{t+1}|ABCDEFGHIJKLMN_{t} | B24: [[['∅'], ['a']], [['A', 'B', 'D', 'E', 'G', 'H', 'J', 'K', 'M', 'N'], ['b', 'c', 'd', 'e', 'f', 'g', 'h', 'i', 'j', 'k', 'l', 'm', 'n']]] | C24: 0 | D24: 0.89385247 | E24: [[['∅'], ['l']], [['A', 'B', 'D', 'E', 'G', 'H', 'J', 'K', 'M', 'N'], ['a', 'b', 'c', 'd', 'e', 'f', 'g', 'h', 'i', 'j', 'k', 'm', 'n']]] | F24: 0 | G24: 0.33225679 | H24: [[['∅'],['m']],[['A','B','D','E','G','H','J','K','M','N'],['a','b','c','d','e','f','g','h','i','j','k','l','n']]] | I24: 0 | J24: 0.095818043 | K24: =IF('15B elementos'!$F24=0, IF('15B elementos'!$I24=0, 0, "Indefinido"), ABS('15B elementos'!$F24-'15B elementos'!$I24)/'15B elementos'!$F24) -> 0 | L24: 0 | M24: ='15B elementos'!$G24/'15B elementos'!$J24 -> 3.4675807
A25: ABDEGHJKMN_{t+1}|BCDEFGHIJKLMNO_{t} | B25: [[['∅'], ['b']], [['A', 'B', 'D', 'E', 'G', 'H', 'J', 'K', 'M', 'N'], ['c', 'd', 'e', 'f', 'g', 'h', 'i', 'j', 'k', 'l', 'm', 'n', 'o']]] | C25: 0 | D25: 0.84216714 | E25: [[['∅'], ['o']], [['A', 'B', 'D', 'E', 'G', 'H', 'J', 'K', 'M', 'N'], ['b', 'c', 'd', 'e', 'f', 'g', 'h', 'i', 'j', 'k', 'l', 'm', 'n']]] | F25: 0 | G25: 0.36576629 | H25: [[['∅'],['o']],[['A','B','D','E','G','H','J','K','M','N'],['b','c','d','e','f','g','h','i','j','k','l','m','n']]] | I25: 0 | J25: 1.6353416 | K25: =IF('15B elementos'!$F25=0, IF('15B elementos'!$I25=0, 0, "Indefinido"), ABS('15B elementos'!$F25-'15B elementos'!$I25)/'15B elementos'!$F25) -> 0 | L25: 1 | M25: ='15B elementos'!$G25/'15B elementos'!$J25 -> 0.22366353
A26: ABCDEFGHIJKLMNO_{t+1}|ACEGIKMO_{t} | E26: [[['N'], ['∅']], [['A', 'B', 'C', 'D', 'E', 'F', 'G', 'H', 'I', 'J', 'K', 'L', 'M', 'O'], ['a', 'c', 'e', 'g', 'i', 'k', 'm', 'o']]] | F26: 9.9778175e-05 | G26: 0.34602213 | H26: [[['L'],['∅']],[['A','B','C','D','E','F','G','H','I','J','K','M','N','O'],['a','e','i','m']]] | I26: 0.0041897893 | J26: 0.47688818 | K26: =IF('15B elementos'!$F26=0, IF('15B elementos'!$I26=0, 0, "Indefinido"), ABS('15B elementos'!$F26-'15B elementos'!$I26)/'15B elementos'!$F26) -> 40.991039 | L26: 0 | M26: ='15B elementos'!$G26/'15B elementos'!$J26 -> 0.72558336
A27: BCDEFGHIJKLMN_{t+1}|ABDEGHJKMN_{t} | E27: [[['D'], ['∅']], [['B', 'C', 'E', 'F', 'G', 'H', 'I', 'J', 'K', 'L', 'M', 'N'], ['a', 'b', 'd', 'e', 'g', 'h', 'j', 'k', 'm', 'n']]] | F27: 0.00076055527 | G27: 0.17557979 | H27: [[['N'],['∅']],[['B','C','D','E','F','G','H','I','J','K','L','M'],['a','b','e','g','j','k','n']]] | I27: 0.0013378263 | J27: 0.51998758 | K27: =IF('15B elementos'!$F27=0, IF('15B elementos'!$I27=0, 0, "Indefinido"), ABS('15B elementos'!$F27-'15B elementos'!$I27)/'15B elementos'!$F27) -> 0.75901254 | L27: 0 | M27: ='15B elementos'!$G27/'15B elementos'!$J27 -> 0.3376615
A28: ACEGIKMO_{t+1}|ABCDEFGHIJKLMNO_{t} | B28: [[['∅'], ['a']], [['A', 'C', 'E', 'G', 'I', 'K', 'M', 'O'], ['b', 'c', 'd', 'e', 'f', 'g', 'h', 'i', 'j', 'k', 'l', 'm', 'n', 'o']]] | C28: 0 | D28: 6.8858573 | E28: [[['∅'], ['n']], [['A', 'C', 'E', 'G', 'I', 'K', 'M', 'O'], ['a', 'b', 'c', 'd', 'e', 'f', 'g', 'h', 'i', 'j', 'k', 'l', 'm', 'o']]] | F28: 0 | G28: 0.46815586 | H28: [[['∅'],['o']],[['A','C','E','G','I','K','M','O'],['a','b','c','d','e','f','g','h','i','j','k','l','m','n']]] | I28: 0 | J28: 0.1774857 | K28: =IF('15B elementos'!$F28=0, IF('15B elementos'!$I28=0, 0, "Indefinido"), ABS('15B elementos'!$F28-'15B elementos'!$I28)/'15B elementos'!$F28) -> 0 | L28: 0 | M28: ='15B elementos'!$G28/'15B elementos'!$J28 -> 2.6377102
A29: ABDEGHJKMN_{t+1}|BCDEFGHIJKLMN_{t} | B29: [[['∅'], ['b']], [['A', 'B', 'D', 'E', 'G', 'H', 'J', 'K', 'M', 'N'], ['c', 'd', 'e', 'f', 'g', 'h', 'i', 'j', 'k', 'l', 'm', 'n']]] | C29: 0 | D29: 0.8586359 | E29: [[['∅'], ['n']], [['A', 'B', 'D', 'E', 'G', 'H', 'J', 'K', 'M', 'N'], ['b', 'c', 'd', 'e', 'f', 'g', 'h', 'i', 'j', 'k', 'l', 'm']]] | F29: 0 | G29: 0.23533607 | H29: [[['∅'],['g']],[['A','B','D','E','G','H','J','K','M','N'],['b','c','d','e','f','h','i','j','k','l','m','n']]] | I29: 0 | J29: 0.5893929 | K29: =IF('15B elementos'!$F29=0, IF('15B elementos'!$I29=0, 0, "Indefinido"), ABS('15B elementos'!$F29-'15B elementos'!$I29)/'15B elementos'!$F29) -> 0 | L29: 0 | M29: ='15B elementos'!$G29/'15B elementos'!$J29 -> 0.39928554
A30: ABCDEFGHIJKLMNO_{t+1}|BDFHJLN_{t} | E30: [[['L'], ['∅']], [['A', 'B', 'C', 'D', 'E', 'F', 'G', 'H', 'I', 'J', 'K', 'M', 'N', 'O'], ['b', 'd', 'f', 'h', 'j', 'l', 'n']]] | F30: 0.0002014637 | G30: 0.29859567 | H30: [[['E'],['∅']],[['A','B','C','D','F','G','H','I','J','K','L','M','N','O'],['d','h','l']]] | I30: 0.0070973635 | J30: 0.4651382 | K30: =IF('15B elementos'!$F30=0, IF('15B elementos'!$I30=0, 0, "Indefinido"), ABS('15B elementos'!$F30-'15B elementos'!$I30)/'15B elementos'!$F30) -> 34.228994 | L30: 0 | M30: ='15B elementos'!$G30/'15B elementos'!$J30 -> 0.64195043
A31: ABCDEFGHIJKLMN_{t+1}|ACEGIKMO_{t} | E31: [[['N'], ['∅']], [['A', 'B', 'C', 'D', 'E', 'F', 'G', 'H', 'I', 'J', 'K', 'L', 'M'], ['a', 'c', 'e', 'g', 'i', 'k', 'm', 'o']]] | F31: 9.9778175e-05 | G31: 0.25478911 | H31: [[['L'],['∅']],[['A','B','C','D','E','F','G','H','I','J','K','M','N'],['a','e','i','m']]] | I31: 0.0041897893 | J31: 0.50172043 | K31: =IF('15B elementos'!$F31=0, IF('15B elementos'!$I31=0, 0, "Indefinido"), ABS('15B elementos'!$F31-'15B elementos'!$I31)/'15B elementos'!$F31) -> 40.991039 | L31: 0 | M31: ='15B elementos'!$G31/'15B elementos'!$J31 -> 0.50783085
A32: BCDEFGHIJKLMNO_{t+1}|ACEGIKMO_{t} | E32: [[['N'], ['∅']], [['B', 'C', 'D', 'E', 'F', 'G', 'H', 'I', 'J', 'K', 'L', 'M', 'O'], ['a', 'c', 'e', 'g', 'i', 'k', 'm', 'o']]] | F32: 9.9778175e-05 | G32: 0.17688775 | H32: [[['L'],['∅']],[['B','C','D','E','F','G','H','I','J','K','M','N','O'],['a','e','i','m']]] | I32: 0.0041897893 | J32: 0.019664526 | K32: =IF('15B elementos'!$F32=0, IF('15B elementos'!$I32=0, 0, "Indefinido"), ABS('15B elementos'!$F32-'15B elementos'!$I32)/'15B elementos'!$F32) -> 40.991039 | L32: 0 | M32: ='15B elementos'!$G32/'15B elementos'!$J32 -> 8.9952715
A33: ACEGIKMO_{t+1}|ABCDEFGHIJKLMN_{t} | B33: [[['∅'], ['a']], [['A', 'C', 'E', 'G', 'I', 'K', 'M', 'O'], ['b', 'c', 'd', 'e', 'f', 'g', 'h', 'i', 'j', 'k', 'l', 'm', 'n']]] | C33: 0 | D33: 0.64955425 | E33: [[['∅'], ['l']], [['A', 'C', 'E', 'G', 'I', 'K', 'M', 'O'], ['a', 'b', 'c', 'd', 'e', 'f', 'g', 'h', 'i', 'j', 'k', 'm', 'n']]] | F33: 0 | G33: 0.24377203 | H33: [[['∅'],['m']],[['A','C','E','G','I','K','M','O'],['a','b','c','d','e','f','g','h','i','j','k','l','n']]] | I33: 0 | J33: 0.089427948 | K33: =IF('15B elementos'!$F33=0, IF('15B elementos'!$I33=0, 0, "Indefinido"), ABS('15B elementos'!$F33-'15B elementos'!$I33)/'15B elementos'!$F33) -> 0 | L33: 0 | M33: ='15B elementos'!$G33/'15B elementos'!$J33 -> 2.7259043
A34: ACEGIKMO_{t+1}|BCDEFGHIJKLMNO_{t} | B34: [[['∅'], ['b']], [['A', 'C', 'E', 'G', 'I', 'K', 'M', 'O'], ['c', 'd', 'e', 'f', 'g', 'h', 'i', 'j', 'k', 'l', 'm', 'n', 'o']]] | C34: 0 | D34: 0.5894556 | E34: [[['∅'], ['m']], [['A', 'C', 'E', 'G', 'I', 'K', 'M', 'O'], ['b', 'c', 'd', 'e', 'f', 'g', 'h', 'i', 'j', 'k', 'l', 'n', 'o']]] | F34: 0 | G34: 0.35472274 | H34: [[['∅'],['o']],[['A','C','E','G','I','K','M','O'],['b','c','d','e','f','g','h','i','j','k','l','m','n']]] | I34: 0 | J34: 0.09041357 | K34: =IF('15B elementos'!$F34=0, IF('15B elementos'!$I34=0, 0, "Indefinido"), ABS('15B elementos'!$F34-'15B elementos'!$I34)/'15B elementos'!$F34) -> 0 | L34: 0 | M34: ='15B elementos'!$G34/'15B elementos'!$J34 -> 3.9233351
A35: BDFHJLN_{t+1}|ABCDEFGHIJKLMNO_{t} | B35: [[['∅'], ['a']], [['B', 'D', 'F', 'H', 'J', 'L', 'N'], ['b', 'c', 'd', 'e', 'f', 'g', 'h', 'i', 'j', 'k', 'l', 'm', 'n', 'o']]] | C35: 0 | D35: 0.70327377 | E35: [[['∅'], ['h']], [['B', 'D', 'F', 'H', 'J', 'L', 'N'], ['a', 'b', 'c', 'd', 'e', 'f', 'g', 'i', 'j', 'k', 'l', 'm', 'n', 'o']]] | F35: 0 | G35: 0.82558131 | H35: [[['∅'],['o']],[['B','D','F','H','J','L','N'],['a','b','c','d','e','f','g','h','i','j','k','l','m','n']]] | I35: 0 | J35: 0.16971087 | K35: =IF('15B elementos'!$F35=0, IF('15B elementos'!$I35=0, 0, "Indefinido"), ABS('15B elementos'!$F35-'15B elementos'!$I35)/'15B elementos'!$F35) -> 0 | L35: 0 | M35: ='15B elementos'!$G35/'15B elementos'!$J35 -> 4.8646341
A36: ABCDEFGHIJKLMN_{t+1}|BDFHJLN_{t} | E36: [[['L'], ['∅']], [['A', 'B', 'C', 'D', 'E', 'F', 'G', 'H', 'I', 'J', 'K', 'M', 'N'], ['b', 'd', 'f', 'h', 'j', 'l', 'n']]] | F36: 0.0002014637 | G36: 0.19995928 | H36: [[['E'],['∅']],[['A','B','C','D','F','G','H','I','J','K','L','M','N'],['d','h','l']]] | I36: 0.0070973635 | J36: 0.37964702 | K36: =IF('15B elementos'!$F36=0, IF('15B elementos'!$I36=0, 0, "Indefinido"), ABS('15B elementos'!$F36-'15B elementos'!$I36)/'15B elementos'!$F36) -> 34.228994 | L36: 0 | M36: ='15B elementos'!$G36/'15B elementos'!$J36 -> 0.52669788
A37: BCDEFGHIJKLMNO_{t+1}|BDFHJLN_{t} | E37: [[['L'], ['∅']], [['B', 'C', 'D', 'E', 'F', 'G', 'H', 'I', 'J', 'K', 'M', 'N', 'O'], ['b', 'd', 'f', 'h', 'j', 'l', 'n']]] | F37: 0.0002014637 | G37: 0.17084551 | H37: [[['E'],['∅']],[['B','C','D','F','G','H','I','J','K','L','M','N','O'],['d','h','l']]] | I37: 0.0070973635 | J37: 0.5145514 | K37: =IF('15B elementos'!$F37=0, IF('15B elementos'!$I37=0, 0, "Indefinido"), ABS('15B elementos'!$F37-'15B elementos'!$I37)/'15B elementos'!$F37) -> 34.228994 | L37: 0 | M37: ='15B elementos'!$G37/'15B elementos'!$J37 -> 0.33202807
A38: BCDEFGHIJKLMN_{t+1}|ACEGIKMO_{t} | E38: [[['N'], ['∅']], [['B', 'C', 'D', 'E', 'F', 'G', 'H', 'I', 'J', 'K', 'L', 'M'], ['a', 'c', 'e', 'g', 'i', 'k', 'm', 'o']]] | F38: 9.9778175e-05 | G38: 0.13680935 | H38: [[['L'],['∅']],[['B','C','D','E','F','G','H','I','J','K','M','N'],['a','e','i','m']]] | I38: 0.0041897893 | J38: 0.35796595 | K38: =IF('15B elementos'!$F38=0, IF('15B elementos'!$I38=0, 0, "Indefinido"), ABS('15B elementos'!$F38-'15B elementos'!$I38)/'15B elementos'!$F38) -> 40.991039 | L38: 0 | M38: ='15B elementos'!$G38/'15B elementos'!$J38 -> 0.38218537
A39: ACEGIKMO_{t+1}|BCDEFGHIJKLMN_{t} | B39: [[['∅'], ['b']], [['A', 'C', 'E', 'G', 'I', 'K', 'M', 'O'], ['c', 'd', 'e', 'f', 'g', 'h', 'i', 'j', 'k', 'l', 'm', 'n']]] | C39: 0 | D39: 0.59825635 | E39: [[['∅'], ['l']], [['A', 'C', 'E', 'G', 'I', 'K', 'M', 'O'], ['b', 'c', 'd', 'e', 'f', 'g', 'h', 'i', 'j', 'k', 'm', 'n']]] | F39: 0 | G39: 0.34097862 | H39: [[['∅'],['g']],[['A','C','E','G','I','K','M','O'],['b','c','d','e','f','h','i','j','k','l','m','n']]] | I39: 0 | J39: 0.5790379 | K39: =IF('15B elementos'!$F39=0, IF('15B elementos'!$I39=0, 0, "Indefinido"), ABS('15B elementos'!$F39-'15B elementos'!$I39)/'15B elementos'!$F39) -> 0 | L39: 0 | M39: ='15B elementos'!$G39/'15B elementos'!$J39 -> 0.58887099
A40: BDFHJLN_{t+1}|ABCDEFGHIJKLMN_{t} | B40: [[['∅'], ['a']], [['B', 'D', 'F', 'H', 'J', 'L', 'N'], ['b', 'c', 'd', 'e', 'f', 'g', 'h', 'i', 'j', 'k', 'l', 'm', 'n']]] | C40: 0 | D40: 0.58825111 | E40: [[['∅'], ['n']], [['B', 'D', 'F', 'H', 'J', 'L', 'N'], ['a', 'b', 'c', 'd', 'e', 'f', 'g', 'h', 'i', 'j', 'k', 'l', 'm']]] | F40: 0 | G40: 0.35857725 | H40: [[['∅'],['m']],[['B','D','F','H','J','L','N'],['a','b','c','d','e','f','g','h','i','j','k','l','n']]] | I40: 0 | J40: 0.078887463 | K40: =IF('15B elementos'!$F40=0, IF('15B elementos'!$I40=0, 0, "Indefinido"), ABS('15B elementos'!$F40-'15B elementos'!$I40)/'15B elementos'!$F40) -> 0 | L40: 0 | M40: ='15B elementos'!$G40/'15B elementos'!$J40 -> 4.5454276
A41: BDFHJLN_{t+1}|BCDEFGHIJKLMNO_{t} | B41: [[['∅'], ['b']], [['B', 'D', 'F', 'H', 'J', 'L', 'N'], ['c', 'd', 'e', 'f', 'g', 'h', 'i', 'j', 'k', 'l', 'm', 'n', 'o']]] | C41: 0 | D41: 0.54690814 | E41: [[['∅'], ['o']], [['B', 'D', 'F', 'H', 'J', 'L', 'N'], ['b', 'c', 'd', 'e', 'f', 'g', 'h', 'i', 'j', 'k', 'l', 'm', 'n']]] | F41: 0 | G41: 0.19199228 | H41: [[['∅'],['o']],[['B','D','F','H','J','L','N'],['b','c','d','e','f','g','h','i','j','k','l','m','n']]] | I41: 0 | J41: 0.081706047 | K41: =IF('15B elementos'!$F41=0, IF('15B elementos'!$I41=0, 0, "Indefinido"), ABS('15B elementos'!$F41-'15B elementos'!$I41)/'15B elementos'!$F41) -> 0 | L41: 1 | M41: ='15B elementos'!$G41/'15B elementos'!$J41 -> 2.3497928
